Workbook

Sheet Анализ по мес
B3: Апрель
B4: Бренд | C4: Количество | D4: Ср маржа | E4: Маржа всего | F4: ДО всего | G4: К получению
B5: KIA | C5: 463 | D5: 605417.44 | E5: 280308275 | F5: 84053500 | G5: 364361775
B6: Chevrolet | C6: 858 | D6: 264234.29 | E6: 2.2671283e+08 | F6: 950000 | G6: 2.2766283e+08
B7: JAC | C7: 190 | D7: 578658.6 | E7: 109945150 | F7: 2550000 | G7: 112495150
B8: JETOUR | C8: 436 | D8: 659702.06 | E8: 287630100 | F8: 3992200 | G8: 291622300
B9: Тотал | C9: 1947 | D9: 464610.44 | E9: 9.0459635e+08 | F9: 91545700 | G9: 9.9614205e+08
B11: Май
B12: Бренд | C12: Количество | D12: Ср маржа | E12: Маржа всего | F12: ДО всего | G12: К получению
B13: KIA | C13: 409 | D13: 534787.24 | E13: 2.1611918e+08 | F13: 61325470 | G13: 2.7744465e+08
B14: Chevrolet | C14: 768 | D14: 261982.81 | E14: 201202800 | F14: 600000 | G14: 201802800
B15: JAC | C15: 236 | D15: 470619.49 | E15: 111066200 | F15: 4950000 | G15: 116016200
B16: JETOUR | C16: 423 | D16: 686793.41 | E16: 256322400 | F16: 2283500 | G16: 258605900
B17: Тотал | C17: 1836 | D17: 447445.86 | E17: 7.8471058e+08 | F17: 69158970 | G17: 8.5386955e+08
B19: Июнь
B20: Бренд | C20: Количество | D20: Ср маржа | E20: Маржа всего | F20: ДО всего | G20: К получению
B21: KIA | C21: 507 | D21: 448667.95 | E21: 223258750 | F21: 52605000 | G21: 275863750
B22: Chevrolet | C22: 788 | D22: 271441.62 | E22: 213896000 | F22: 9500500 | G22: 223396500
B23: JAC | C23: 244 | D23: 446697.13 | E23: 108994100 | F23: 7050000 | G23: 116044100
B24: JETOUR | C24: 467 | D24: 629376.87 | E24: 293919000 | F24: 3162500 | G24: 297081500
B25: Тотал | C25: 2006 | D25: 420879.24 | E25: 840067850 | F25: 72318000 | G25: 912385850
B27: Июль
B28: Бренд | C28: Количество | D28: Ср маржа | E28: Маржа всего | F28: ДО всего | G28: К получению
B29: KIA | C29: 472 | D29: 473325.42 | E29: 214309700 | F29: 56939300 | G29: 271249000
B30: Chevrolet | C30: 1189 | D30: 239705.63 | E30: 285010000 | F30: 135916500 | G30: 420926500
B31: JAC | C31: 326 | D31: 323326.53 | E31: 105404450 | F31: 7990000 | G31: 113394450
B32: JETOUR | C32: 404 | D32: 656017.33 | E32: 265031000 | F32: 1210500 | G32: 266241500
B33: Тотал | C33: 2391 | D33: 367567.98 | E33: 869755150 | F33: 202056300 | G33: 1071811450
B35: Август
B36: Бренд | C36: Количество | D36: Ср маржа | E36: Маржа всего | F36: ДО всего | G36: К получению
B37: KIA | C37: 457 | D37: 570560.63 | E37: 257149810 | F37: 66976600 | G37: 324126410
B38: Chevrolet | C38: 809 | D38: 227305.32 | E38: 183890000 | F38: 84787400 | G38: 268677400
B39: JAC | C39: 247 | D39: 304207.69 | E39: 75139300 | F39: 2744400 | G39: 77883700
B40: JETOUR | C40: 259 | D40: 685496.53 | E40: 177543600 | F40: 2248100 | G40: 179791700
B41: Тотал | C41: 1772 | D41: 393520.94 | E41: 693722710 | F41: 156756500 | G41: 850479210
B43: Сентябрь
B44: Бренд | C44: Количество | D44: Ср маржа | E44: Маржа всего | F44: ДО всего | G44: К получению
B45: KIA | C45: 407 | D45: 702001.91 | E45: 285714779 | F45: 62820010 | G45: 348534789
B46: Chevrolet | C46: 948 | D46: 250200.42 | E46: 237190000 | F46: 117355900 | G46: 354545900
B47: JAC | C47: 197 | D47: 346040.36 | E47: 68169950 | F47: 2427700 | G47: 70597650
...

Sheet Анализ Киа
A3: Названия строк | B3: Кол | C3: РРЦ | D3: Маржа тотал | E3: Скидка | F3: Маржа после скидокк | G3: Доп | H3: Средний маржа | I3: %
A4: 1069 Актау TOO «DCG Aktau» (KIA) | B4: 18 | C4: 14054433 | D4: 12585739 | E4: 359800 | F4: 12225939 | G4: 2942000 | H4: =F4/B4 -> 679218.83 | I4: =H4/C4 -> 0.048327728
A5: 1151 Алматы ТОО «DCG Qulja» (KIA) | B5: 57 | C5: 14670702 | D5: 41978400 | E5: 6980000 | F5: 34998400 | G5: 8300000 | H5: =F5/B5 -> 614007.02 | I5: =H5/C5 -> 0.0418526
A6: 331 Шымкент ТОО «DCG ONTUSTIK» (KIA) | B6: 125 | C6: 14035600 | D6: 85360200 | E6: 216000 | F6: 85144200 | G6: 29148100 | H6: =F6/B6 -> 681153.6 | I6: =H6/C6 -> 0.048530423
A7: 363 Алматы ТОО «DCG ALMATY» (KIA) | B7: 59 | C7: 13784915 | D7: 35633650 | E7: 2018400 | F7: 33615250 | G7: 6050000 | H7: =F7/B7 -> 569750 | I7: =H7/C7 -> 0.041331411
A8: 365 Тараз ТОО «DCGTARAZ» (KIA) | B8: 23 | C8: 13916087 | D8: 14232300 | E8: 600000 | F8: 13632300 | G8: 7650000 | H8: =F8/B8 -> 592708.7 | I8: =H8/C8 -> 0.042591621
A9: 371 Астана ТОО «DCG ASTANA» (KIA) | B9: 65 | C9: 14362308 | D9: 40969400 | E9: 290000 | F9: 40679400 | G9: 8690000 | H9: =F9/B9 -> 625836.92 | I9: =H9/C9 -> 0.043574956
A10: 735 Усть-Каменогорск ТОО «DCG VOSTOK» (KIA) | B10: 34 | C10: 13328235 | D10: 20042050 | E10: 1800000 | F10: 18242050 | G10: 4100000 | H10: =F10/B10 -> 536530.88 | I10: =H10/C10 -> 0.040255208
A11: 863 Павлодар ТОО «DCG ERTIS» (KIA) | B11: 27 | C11: 13975185 | D11: 19465600 | E11: 0 | F11: 19465600 | G11: 0 | H11: =F11/B11 -> 720948.15 | I11: =H11/C11 -> 0.051587735
A12: Общий итог | B12: 408 | C12: 14071274 | D12: 270267339 | E12: 12264200 | F12: 258003139 | G12: 66880100 | H12: =F12/B12 -> 632360.63 | I12: =H12/C12 -> 0.044939828
A18: Модель | B18: Кол | C18: РРЦ | D18: Маржаа | E18: % | F18: % авто
A19: Carnival | B19: 3 | C19: 24323333 | D19: 1234416.7 | E19: =D19/C19 -> 0.050750308 | F19: =B19/$B$32 -> 0.0073529412
A20: Ceed | B20: 6 | C20: 9890000 | D20: 437641.67 | E20: =D20/C20 -> 0.044250927 | F20: =B20/$B$32 -> 0.014705882
A21: Ceed SW | B21: 10 | C21: 11390000 | D21: 512550 | E21: =D21/C21 -> 0.045 | F21: =B21/$B$32 -> 0.024509804
A22: Cerato | B22: 48 | C22: 10437917 | D22: 382550 | E22: =D22/C22 -> 0.036650034 | F22: =B22/$B$32 -> 0.11764706
A23: K5 | B23: 91 | C23: 13472418 | D23: 675655.49 | E23: =D23/C23 -> 0.050151021 | F23: =B23/$B$32 -> 0.22303922
A24: K8 | B24: 1 | C24: 26490000 | D24: 1721850 | E24: =D24/C24 -> 0.065 | F24: =B24/$B$32 -> 0.0024509804
A25: Seltos | B25: 26 | C25: 12463077 | D25: 558340.38 | E25: =D25/C25 -> 0.044799562 | F25: =B25/$B$32 -> 0.06372549
A26: Soluto | B26: 38 | C26: 7384736.8 | D26: 298947.37 | E26: =D26/C26 -> 0.04048179 | F26: =B26/$B$32 -> 0.093137255
A27: Sorento 2025 | B27: 61 | C27: 18811311 | D27: 743282.79 | E27: =D27/C27 -> 0.039512545 | F27: =B27/$B$32 -> 0.1495098
A28: Sorento 2026 | B28: 11 | C28: 22390000 | D28: 1123313.6 | E28: =D28/C28 -> 0.050170328 | F28: =B28/$B$32 -> 0.026960784
A29: Soul | B29: 4 | C29: 12015000 | D29: 540675 | E29: =D29/C29 -> 0.045 | F29: =B29/$B$32 -> 0.0098039216
A30: Sportage | B30: 93 | C30: 16023976 | D30: 788217.09 | E30: =D30/C30 -> 0.049189856 | F30: =B30/$B$32 -> 0.22794118
... A32: Общий итог | B32: 408 | C32: 14071274 | D32: 632360.63 | E32: =D32/C32 -> 0.044939828 | F32: =B32/$B$32 -> 1
A35: Сумма скидки | B35: (несколько элементов)
A37: Названия строк | B37: Сумма по полю Кол-во | C37: Сумма по полю Сумма скидки
A38: 1069 Актау TOO «DCG Aktau» (KIA) | B38: 1 | C38: 359800
A39: 1151 Алматы ТОО «DCG Qulja» (KIA) | B39: 3 | C39: 6980000
A40: 331 Шымкент ТОО «DCG ONTUSTIK» (KIA) | B40: 1 | C40: 216000
A41: 363 Алматы ТОО «DCG ALMATY» (KIA) | B41: 6 | C41: 2018400
A42: 365 Тараз ТОО «DCGTARAZ» (KIA) | B42: 1 | C42: 600000
A43: 371 Астана ТОО «DCG ASTANA» (KIA) | B43: 1 | C43: 290000
A44: 735 Усть-Каменогорск ТОО «DCG VOSTOK» (KIA) | B44: 2 | C44: 1800000
A45: Общий итог | B45: 15 | C45: 12264200
A49: Названия строк | B49: Маржаа | C49: Мар инвест
A50: 1069 Актау TOO «DCG Aktau» (KIA) | B50: 12225939 | C50: 1264899
A51: 1151 Алматы ТОО «DCG Qulja» (KIA) | B51: 34998400 | C51: 4181150
A52: 331 Шымкент ТОО «DCG ONTUSTIK» (KIA) | B52: 85144200 | C52: 8772250
A53: 363 Алматы ТОО «DCG ALMATY» (KIA) | B53: 33615250 | C53: 4066550
A54: 365 Тараз ТОО «DCGTARAZ» (KIA) | B54: 13632300 | C54: 1600350
...

Sheet Киа для аналитики
A1: Кол-во | B1: Название ДЦ | C1: Модель KIA | D1: Комплектация KIA | E1: Код модели KIA | F1: VIN KZ | G1: Цвет УС KIA | H1: Модификация | I1: Привод | J1: КПП | K1: Объем двигателя, см3 | L1: Год выпуска | M1: Номер договора | N1: Дата договора | O1: Ответственный | P1: ФИО | Q1: Контакт: ИИН/БИН | R1: Компания: Название компании | S1: Компания: БИН | T1: Цена реализации | U1: Рекомендуемая розничная цена | V1: Сумма скидки | W1: Скидка дистрибуции | X1: Стоимость доп. оборудования | Y1: Максимальное вознаграждение дилера | Z1: Вознаграждение без скидки | AA1: 1s/3s | AB1: Маркетинг | AC1: % | AD1: Маржа | AE1: Маржа после скидок | AF1: Сумма предоплаты, тенге | AG1: Дата подписания акта п/п | AH1: Место реализации (город) | AI1: !Тип продажи а/м | AJ1: Способ приобретения | AK1: Кредит в банке | AL1: Срок кредита в месяцах | AM1: Размер первоначального взноса по кредиту (В процентах) | AN1: Число попаданий на замечания | AO1: Название ДЦ. откуда забрали машину | AP1: Вознаграждение дилера (за перемещённую машину) | AQ1: Компенсация дилера | AR1: Номер карты Технической поддержки Litro | AS1: Дополнительная компенсация дилера | AT1: ID | AU1: Номер телефона | AV1: Завод производитель
A2: 1 | B2: 331 Шымкент ТОО «DCG ONTUSTIK» (KIA) | C2: Seltos | D2: Style | E2: THW52G61Q | F2: MX1ER81AKRK673769 | G2: B3A Neptune Blue / Синий | H2: G0BQ | I2: 4WD | J2: AT | K2: 1999 | L2: 2024 | M2: 331_292944 | N2: 46125 | O2: Ернар Жайдарбек | P2: Селифанова Инна Викторовна | Q2: 780928402396 | T2: 12990000 | U2: 12990000 | V2: 0 | W2: 0 | X2: 0 | Y2: 0 | Z2: 0 | AA2: 3s | AB2: =U2*0.5% -> 64950 | AC2: 0.04 | AD2: =U2*AC2 -> 519600 | AE2: =AD2-V2 -> 519600 | AG2: 46126.917 | AH2: Шымкент | AI2: Безналичный расчет | AJ2: Безналичный | AK2: Без привлечения кредита | AN2: 0 | AP2: 0 | AQ2: 0 | AR2: 132075139 | AT2: 10448600 | AU2: 77015603204 | AV2: САП
A3: 1 | B3: 331 Шымкент ТОО «DCG ONTUSTIK» (KIA) | C3: Sportage | D3: X-Line+ | E3: GYWDL9A1K | F3: MX1PX81FDRK011802 | G3: UD Clear White / Белый | H3: H0D1 | I3: 4WD | J3: AT | K3: 2497 | L3: 2024 | M3: 331_294098 | N3: 46141 | O3: Абдукарим Абдукаим | P3: Ройтман Рустам | Q3: 760211302101 | T3: 15784000 | U3: 16190000 | V3: 216000 | W3: 190000 | X3: 0 | Y3: 0 | Z3: -216000 | AA3: 3s | AB3: =U3*0.5% -> 80950 | AC3: 0.04 | AD3: =U3*AC3 -> 647600 | AE3: =AD3-V3 -> 431600 | AG3: 46142 | AH3: Шымкент | AI3: Безналичный расчет | AJ3: Безналичный | AK3: Без привлечения кредита | AN3: 0 | AP3: 0 | AQ3: 0 | AR3: 132076748 | AT3: 10448618 | AU3: 77077000991 | AV3: САП
A4: 1 | B4: 331 Шымкент ТОО «DCG ONTUSTIK» (KIA) | C4: Ceed | D4: Luxe | E4: J7S6D261F | F4: MX1H2516BSK236164 | G4: H8G Penta Metal / Серый | H4: D2U5 | I4: 2WD | J4: AT | K4: 0 | L4: 2024 | M4: 331_292604 | N4: 46119 | O4: Жандаулет Жұмалиев | P4: Кредина Юлия Александровна | Q4: 871006401238 | T4: 8890000 | U4: 8890000 | V4: 0 | W4: 0 | X4: 0 | Y4: 0 | Z4: 0 | AA4: 3s | AB4: =U4*0.5% -> 44450 | AC4: 0.04 | AD4: =U4*AC4 -> 355600 | AE4: =AD4-V4 -> 355600 | AG4: 46133 | AH4: Шымкент | AI4: Безналичный расчет | AJ4: Безналичный | AK4: Без привлечения кредита | AN4: 0 | AP4: 0 | AQ4: 0 | AR4: 132075639 | AS4: 129900 | AT4: 10685796 | AU4: 77058500030 | AV4: САП
A5: 1 | B5: 331 Шымкент ТОО «DCG ONTUSTIK» (KIA) | C5: Ceed | D5: Comfort | E5: J7S6D261F | F5: MX1H1516BSK239964 | G5: WD Casa White / Белый | H5: S10W | I5: 2WD | J5: AT | K5: 1591 | L5: 2025 | M5: 331_292796 | N5: 46122 | O5: Қаныбек Рахманәлі | P5: Утегенова Кулзат Шаймовна | Q5: 670912402356 | T5: 9690000 | U5: 9690000 | V5: 0 | W5: 0 | X5: 0 | Y5: 436050 | Z5: 436050 | AA5: 3s | AB5: =U5*0.5% -> 48450 | AC5: 0.045 | AD5: =U5*AC5 -> 436050 | AE5: =AD5-V5 -> 436050 | AF5: 2 590 000.00 | AG5: 46128 | AH5: Шымкент | AI5: Кредит | AJ5: Льготное кредитование | AK5: Halyk Bank | AL5: 84 месяца | AM5: 20 | AN5: 0 | AP5: 0 | AQ5: 0 | AR5: 132075335 | AS5: 122900 | AT5: 11010655 | AU5: 77710199162 | AV5: САП
A6: 1 | B6: 331 Шымкент ТОО «DCG ONTUSTIK» (KIA) | C6: Seltos | D6: Luxe | E6: THW52G61V | F6: MX1ER81AESK765870 | G6: KLG Steel Gray / Стальной | H6: G0BM | I6: 2WD | J6: AT | K6: 1999 | L6: 2025 | M6: 331_293611 | N6: 46134 | O6: Абылайхан Нагибек | P6: Файзиев Елнур Хамзаевич | Q6: 840317301462 | T6: 11990000 | U6: 11990000 | V6: 0 | W6: 0 | X6: 0 | Y6: 634050 | Z6: 634050 | AA6: 3s | AB6: =U6*0.5% -> 59950 | AC6: 0.045 | AD6: =U6*AC6 -> 539550 | AE6: =AD6-V6 -> 539550 | AG6: 46135 | AH6: Шымкент | AI6: Безналичный расчет | AJ6: Безналичный | AK6: Без привлечения кредита | AN6: 0 | AP6: 0 | AQ6: 0 | AR6: 132075931 | AS6: 153900 | AT6: 11037821 | AU6: 77077064040 | AV6: САП
A7: 1 | B7: 863 Павлодар ТОО «DCG ERTIS» (KIA) | C7: Ceed | D7: Luxe | E7: J7S6D261F | F7: MX1H2516BSK247884 | G7: H8G Penta Metal / Серый | H7: D2U5 | I7: 2WD | J7: AT | K7: 0 | L7: 2025 | M7: 863_293026 | N7: 46126 | O7: ЕРЖАН КАРАМЕНДИНОВ | P7: Толеу Олжас Жантасулы | Q7: 930224350672 | T7: 10690000 | U7: 10690000 | V7: 0 | W7: 0 | X7: 0 | Y7: 481050 | Z7: 481050 | AA7: 3s | AB7: =U7*0.5% -> 53450 | AC7: 0.045 | AD7: =U7*AC7 -> 481050 | AE7: =AD7-V7 -> 481050 | AF7: 10 690 000.00 | AG7: 46126 | AH7: Павлодар | AI7: Наличный расчет | AJ7: Наличный расчет | AK7: Без привлечения кредита | AM7: 100 | AN7: 0 | AP7: 0 | AQ7: 0 | AR7: 132075156 | AS7: 129900 | AT7: 11090787 | AU7: 77471136340 | AV7: САП
A8: 1 | B8: 363 Алматы ТОО «DCG ALMATY» (KIA) | C8: Ceed SW | D8: Comfort | E8: J7W5D261F | F8: MX1H4816BSK239650 | G8: HW2 Deluxe White / Белый перламутр | H8: K0OP | I8: 2WD | J8: AT | K8: 1591 | L8: 2025 | M8: 363_292472 | N8: 46118 | O8: Бахытжан Смагулов | P8: Нурмухамет Ербол | Q8: 890524301239 | T8: 10990000 | U8: 10990000 | V8: 0 | W8: 0 | X8: 0 | Y8: 494550 | Z8: 494550 | AA8: 1s | AB8: =U8*0.5% -> 54950 | AC8: 0.045 | AD8: =U8*AC8 -> 494550 | AE8: =AD8-V8 -> 494550 | AF8: 10 990 000.00 | AG8: 46120 | AH8: Алматы | AI8: Наличный расчет | AJ8: Наличный расчет | AK8: Без привлечения кредита | AN8: 0 | AP8: 0 | AQ8: 0 | AR8: 132074818 | AS8: 127900 | AT8: 11583852 | AU8: 77777765777 | AV8: САП
A9: 1 | B9: 331 Шымкент ТОО «DCG ONTUSTIK» (KIA) | C9: Seltos | D9: Comfort | E9: THW52G61V | F9: MX1EP81AESK776725 | G9: KDG Gravity Gray / Серый | H9: D395 | I9: 2WD | J9: AT | K9: 1999 | L9: 2025 | M9: 331_294107 | N9: 46141 | O9: Арман Сабыров | P9: Рахимжанов Булат Мырзахметович | Q9: 680127302453 | T9: 10990000 | U9: 10990000 | V9: 0 | W9: 0 | X9: 0 | Y9: 494550 | Z9: 494550 | AA9: 3s | AB9: =U9*0.5% -> 54950 | AC9: 0.045 | AD9: =U9*AC9 -> 494550 | AE9: =AD9-V9 -> 494550 | AF9: 2 198 000.00 | AG9: 46142 | AH9: Шымкент | AI9: Кредит | AJ9: Стандартное кредитование | AK9: Halyk Bank | AL9: 84 месяца | AM9: 20 | AN9: 0 | AO9: 215 Шымкент TOO «NOMAD MOTORS SHYM» (KIA) | AP9: 0 | AQ9: 0 | AR9: 132076704 | AS9: 145900 | AT9: 11608275 | AU9: 77754060101 | AV9: САП
A10: 1 | B10: 331 Шымкент ТОО «DCG ONTUSTIK» (KIA) | C10: Sorento 2025 | D10: Comfort | E10: GZW5L961G | F10: MX1RH81DDSK343433 | G10: AGT Graphite Gray / Серый | H10: G2IF | I10: 4WD | J10: AT | K10: 2497 | L10: 2025 | M10: 331_292593 | N10: 46119 | O10: Нұрсұлтан Көкежан | P10: Сахыбекова Айнур Жаксылыковна | Q10: 760702400654 | T10: 17240000 | U10: 16990000 | V10: 0 | W10: 0 | X10: 250000 | Y10: 934450 | Z10: 934450 | AA10: 3s | AB10: =U10*0.5% -> 84950 | AC10: 0.045 | AD10: =U10*AC10 -> 764550 | AE10: =AD10-V10 -> 764550 | AF10: 3 000 000.00 | AG10: 46127 | AH10: Шымкент | AI10: Кредит | AJ10: Стандартное кредитование | AK10: Банк ЦентрКредит | AL10: 84 месяца | AM10: 20 | AN10: 0 | AO10: 365 Тараз ТОО «DCGTARAZ» (KIA) | AP10: 0 | AQ10: 0 | AS10: 216900 | AT10: 11608558 | AU10: 77073589208 | AV10: САП
A11: 1 | B11: 331 Шымкент ТОО «DCG ONTUSTIK» (KIA) | C11: Cerato | D11: Comfort | E11: DJS4D261F | F11: MX1F3416BSK003073 | G11: KLG Steel Gray / Стальной | H11: D0A6 | I11: 2WD | J11: AT | K11: 1591 | L11: 2025 | M11: 331_292471 | N11: 46118 | O11: Абылайхан Нагибек | P11: Жонеуов Канатбек Жаксылыкбаевич | Q11: 851103301572 | T11: 10310000 | U11: 9990000 | V11: 0 | W11: 0 | X11: 320000 | Y11: 399600 | Z11: 399600 | AA11: 3s | AB11: =U11*0.5% -> 49950 | AC11: 0.04 | AD11: =U11*AC11 -> 399600 | AE11: =AD11-V11 -> 399600 | AF11: 1 031 000.00 | AG11: 46120 | AH11: Шымкент | AI11: Кредит | AJ11: Стандартное кредитование | AK11: Банк ЦентрКредит | AL11: 84 месяца | AM11: 10 | AN11: 0 | AP11: 0 | AQ11: 0 | AR11: 132074816 | AT11: 11608876 | AU11: 77076840585 | AV11: САП
A12: 1 | B12: 735 Усть-Каменогорск ТОО «DCG VOSTOK» (KIA) | C12: K5 | D12: Prestige | E12: EUS42JG1J | F12: MX16A414BSK044694 | G12: SWP Snow White Pearl / Белый перламутр | H12: G156 | I12: 2WD | J12: AT | K12: 1975 | L12: 2025 | M12: 735_293367 | N12: 46131 | O12: Дарын Әмірбеков | P12: Болатов Алмас Болатұлы | Q12: 950309351468 | T12: 14240000 | U12: 13990000 | V12: 0 | W12: 0 | X12: 250000 | Y12: 769450 | Z12: 769450 | AA12: 1s | AB12: =U12*0.5% -> 69950 | AC12: 0.045 | AD12: =U12*AC12 -> 629550 | AE12: =AD12-V12 -> 629550 | AF12: 2 848 000.00 | AG12: 46135 | AH12: Усть-Каменогорск | AI12: Кредит | AJ12: Стандартное кредитование | AK12: Halyk Bank | AL12: 84 месяца | AM12: 20 | AN12: 0 | AP12: 0 | AQ12: 0 | AR12: 132075936 | AS12: 196900 | AT12: 11620509 | AU12: 77027679437 | AV12: САП
A13: 1 | B13: 365 Тараз ТОО «DCGTARAZ» (KIA) | C13: Ceed | D13: Comfort | E13: J7S6D261F | F13: MX1H1516BSK253995 | G13: H8G Penta Metal / Серый | H13: S10W | I13: 2WD | J13: AT | K13: 1591 | L13: 2025 | M13: 365_292181 | N13: 46112 | O13: Тұрар Жеңіс | P13: Сарбаев Ескендір Жұмабайұлы | Q13: 940124301602 | T13: 10240000 | U13: 9690000 | V13: 0 | W13: 0 | X13: 550000 | Y13: 436050 | Z13: 436050 | AA13: 1s | AB13: =U13*0.5% -> 48450 | AC13: 0.045 | AD13: =U13*AC13 -> 436050 | AE13: =AD13-V13 -> 436050 | AF13: 3 500 000.00 | AG13: 46119 | AH13: Тараз | AI13: Кредит | AJ13: Стандартное кредитование | AK13: Евразийский банк | AL13: 84 месяца | AM13: 35 | AN13: 0 | AO13: 331 Шымкент ТОО «DCG ONTUSTIK» (KIA) | AP13: 0 | AQ13: 0 | AR13: 132074730 | AS13: 122900 | AT13: 11704211 | AU13: 77075958349 | AV13: САП
A14: 1 | B14: 863 Павлодар ТОО «DCG ERTIS» (KIA) | C14: Seltos | D14: Luxe | E14: THW52G61V | F14: MX1ER81AESK791864 | G14: KDG Gravity Gray / Серый | H14: G0BM | I14: 2WD | J14: AT | K14: 1999 | L14: 2025 | M14: 863_293237 | N14: 46129 | O14: Алишер Сериков | P14: Сон Виталий Валерьевич | Q14: 820320350314 | T14: 11990000 | U14: 11990000 | V14: 0 | W14: 0 | X14: 0 | Y14: 634050 | Z14: 634050 | AA14: 3s | AB14: =U14*0.5% -> 59950 | AC14: 0.045 | AD14: =U14*AC14 -> 539550 | AE14: =AD14-V14 -> 539550 | AF14: 2 398 000.00 | AG14: 46135 | AH14: Павлодар | AI14: Кредит | AJ14: Льготное кредитование | AK14: Halyk Bank | AL14: 84 месяца | AM14: 20 | AN14: 0 | AP14: 0 | AQ14: 0 | AR14: 132075928 | AS14: 153900 | AT14: 11720930 | AU14: 77015520128 | AV14: САП
A15: 1 | B15: 1151 Алматы ТОО «DCG Qulja» (KIA) | C15: Seltos | D15: Luxe | E15: THW52G61V | F15: MX1ER81AESK792400 | G15: SWP Snow White Pearl / Белый перламутр | H15: G0BM | I15: 2WD | J15: AT | K15: 1999 | L15: 2025 | M15: 1151_293792 | N15: 46140 | O15: Мади Мынбаев | P15: БЕРДЫБАЕВ МУРАТ ЕГИЗБАЕВИЧ | Q15: 670608301765 | T15: 11990000 | U15: 11990000 | V15: 0 | W15: 0 | X15: 0 | Y15: 634050 | Z15: 634050 | AA15: 3s | AB15: =U15*0.5% -> 59950 | AC15: 0.045 | AD15: =U15*AC15 -> 539550 | AE15: =AD15-V15 -> 539550 | AG15: 46142 | AH15: Алматы | AI15: Наличный расчет | AJ15: Наличный расчет | AK15: Без привлечения кредита | AN15: 0 | AO15: 331 Шымкент ТОО «DCG ONTUSTIK» (KIA) | AP15: 0 | AQ15: 0 | AS15: 153900 | AT15: 11720969 | AU15: 77025388525 | AV15: САП
A16: 1 | B16: 365 Тараз ТОО «DCGTARAZ» (KIA) | C16: Seltos | D16: Luxe | E16: THW52G61V | F16: MX1ER81AESK790601 | G16: FSB Modern Black / Черный | H16: G0BM | I16: 2WD | J16: AT | K16: 1999 | L16: 2025 | M16: 365_293027 | N16: 46126 | O16: Сұлтан Пойызбаев | P16: Мамышева Бекзат Бауржановна | Q16: 861106400453 | T16: 11990000 | U16: 11990000 | V16: 0 | W16: 0 | X16: 0 | Y16: 634050 | Z16: 634050 | AA16: 1s | AB16: =U16*0.5% -> 59950 | AC16: 0.045 | AD16: =U16*AC16 -> 539550 | AE16: =AD16-V16 -> 539550 | AF16: 2 398 000.00 | AG16: 46133 | AH16: Тараз | AI16: Кредит | AJ16: Льготное кредитование | AK16: Halyk Bank | AL16: 84 месяца | AM16: 20 | AN16: 0 | AP16: 0 | AQ16: 0 | AR16: 132075670 | AS16: 153900 | AT16: 11721007 | AU16: 77011301532 | AV16: САП
A17: 1 | B17: 1151 Алматы ТОО «DCG Qulja» (KIA) | C17: K5 | D17: Prestige | E17: EUS42JG1J | F17: MX16A414BSK045226 | G17: AG2 Graphite Gray / Серый | H17: G156 | I17: 2WD | J17: AT | K17: 1975 | L17: 2025 | M17: 1151_292671 | N17: 46120 | O17: НУРСУЛТАН КУРПЕТАЕВ | P17: Елюбаев Асхат Болатович | Q17: 931031300644 | T17: 14390000 | U17: 13990000 | V17: 0 | W17: 0 | X17: 400000 | Y17: 769450 | Z17: 769450 | AA17: 3s | AB17: =U17*0.5% -> 69950 | AC17: 0.055 | AD17: =U17*AC17 -> 769450 | AE17: =AD17-V17 -> 769450 | AF17: 1 439 000.00 | AG17: 46127 | AH17: Алматы | AI17: Кредит | AJ17: Льготное кредитование | AK17: Банк ЦентрКредит | AL17: 84 месяца | AM17: 10 | AN17: 0 | AO17: 343 Талдыкорган ТОО «Taldykorgan Auto Group» (KIA) | AP17: 0 | AQ17: 0 | AR17: 132075227 | AS17: 196900 | AT17: 11722414 | AU17: 77017227200 | AV17: САП
A18: 1 | B18: 863 Павлодар ТОО «DCG ERTIS» (KIA) | C18: K5 | D18: Prestige | E18: EUS42JG1J | F18: MX16A414BSK045214 | G18: AG2 Graphite Gray / Серый | H18: G156 | I18: 2WD | J18: AT | K18: 1975 | L18: 2025 | M18: 863_293722 | N18: 46136 | O18: КАНАТ АЛЬЖАНОВ | P18: Сатвалдинов Айтуган Закирьянович | Q18: 660124300308 | T18: 13990000 | U18: 13990000 | V18: 0 | W18: 0 | X18: 0 | Y18: 769450 | Z18: 769450 | AA18: 3s | AB18: =U18*0.5% -> 69950 | AC18: 0.055 | AD18: =U18*AC18 -> 769450 | AE18: =AD18-V18 -> 769450 | AF18: 11 000 000.00 | AG18: 46142 | AH18: Павлодар | AI18: Кредит | AJ18: Стандартное кредитование | AK18: Банк ЦентрКредит | AL18: 36 месяцев | AM18: 79 | AN18: 0 | AP18: 0 | AQ18: 0 | AR18: 132076523 | AS18: 196900 | AT18: 11724906 | AU18: 77778640891 | AV18: САП
A19: 1 | B19: 1151 Алматы ТОО «DCG Qulja» (KIA) | C19: Sportage | D19: Luxe | E19: GYWD2J61G | F19: MX1PV81DDSK016882 | G19: FSB Modern Black / Черный | H19: G0P1 | I19: 4WD | J19: AT | K19: 1999 | L19: 2025 | M19: 1151_293318 | N19: 46132 | O19: Дайана Калиаскар | P19: ЕРБОЛАТОВА ДАНА РИШАДОВНА | Q19: 960516450532 | T19: 13490000 | U19: 13490000 | V19: 0 | W19: 0 | X19: 0 | Y19: 741950 | Z19: 741950 | AA19: 3s | AB19: =U19*0.5% -> 67450 | AC19: 0.055 | AD19: =U19*AC19 -> 741950 | AE19: =AD19-V19 -> 741950 | AF19: 2 690 000.00 | AG19: 46139 | AH19: Алматы | AI19: Льготный кредит | AJ19: Льготное кредитование | AK19: Банк ЦентрКредит | AL19: 84 месяца | AM19: 19 | AN19: 0 | AO19: 363 Алматы ТОО «DCG ALMATY» (KIA) | AP19: 0 | AQ19: 0 | AR19: 132076104 | AS19: 181900 | AT19: 11740393 | AU19: 77054991469 | AV19: САП
A20: 1 | B20: 371 Астана ТОО «DCG ASTANA» (KIA) | C20: K5 | D20: Prestige | E20: EUS42JG1J | F20: MX16A414BSK045168 | G20: ABP Aurora Black Pearl / Чёрный перламутр | H20: G156 | I20: 2WD | J20: AT | K20: 1975 | L20: 2025 | M20: 371_292248 | N20: 46114 | O20: Даурен Манкулов | P20: Музафаров Дархан Шарафиденович | Q20: 920708350552 | T20: 13990000 | U20: 13990000 | V20: 0 | W20: 0 | X20: 0 | Y20: 769450 | Z20: 769450 | AA20: 1s | AB20: =U20*0.5% -> 69950 | AC20: 0.045 | AD20: =U20*AC20 -> 629550 | AE20: =AD20-V20 -> 629550 | AF20: 7 000 000.00 | AG20: 46125 | AH20: Астана | AI20: Кредит | AJ20: Стандартное кредитование | AK20: Береке Банк | AL20: 84 месяца | AM20: 50 | AN20: 0 | AP20: 0 | AQ20: 0 | AR20: 132075060 | AS20: 196900 | AT20: 11741552 | AU20: 77055882200 | AV20: САП
A21: 1 | B21: 371 Астана ТОО «DCG ASTANA» (KIA) | C21: Cerato | D21: Luxe+ | E21: DJS4D261F | F21: MX1F4416BSK003629 | G21: UD Clear White / Белый | H21: G02O | I21: 2WD | J21: AT | K21: 1591 | L21: 2025 | M21: 371_292337 | N21: 46116 | O21: Жансерик Туркменов | P21: Негделхан Макпал | Q21: 900313451195 | T21: 10490000 | U21: 10490000 | V21: 0 | W21: 0 | X21: 0 | Y21: 419600 | Z21: 419600 | AA21: 1s | AB21: =U21*0.5% -> 52450 | AC21: 0.04 | AD21: =U21*AC21 -> 419600 | AE21: =AD21-V21 -> 419600 | AF21: 7 394 228.00 | AG21: 46119 | AH21: Астана | AI21: Кредит | AJ21: Стандартное кредитование | AK21: Банк ЦентрКредит | AL21: 84 месяца | AM21: 75 | AN21: 0 | AP21: 0 | AQ21: 0 | AR21: 132074721 | AT21: 11748607 | AU21: 77752940222 | AV21: САП
A22: 1 | B22: 331 Шымкент ТОО «DCG ONTUSTIK» (KIA) | C22: Cerato | D22: Comfort | E22: DJS4D261F | F22: MX1F3416BSK003954 | G22: KLG Steel Gray / Стальной | H22: D0A6 | I22: 2WD | J22: AT | K22: 1591 | L22: 2025 | M22: 331_291802 | N22: 46109 | O22: Арман Сабыров | P22: Усманов Максат Заркинович | Q22: 850818303157 | T22: 10540000 | U22: 9990000 | V22: 0 | W22: 0 | X22: 550000 | Y22: 399600 | Z22: 399600 | AA22: 3s | AB22: =U22*0.5% -> 49950 | AC22: 0.04 | AD22: =U22*AC22 -> 399600 | AE22: =AD22-V22 -> 399600 | AF22: 2 000 000.00 | AG22: 46120 | AH22: Шымкент | AI22: Кредит | AJ22: Стандартное кредитование | AK22: МФО Sapa Digital Finance | AL22: 84 месяца | AM22: 10 | AN22: 0 | AO22: 215 Шымкент TOO «NOMAD MOTORS SHYM» (KIA) | AP22: 0 | AQ22: 0 | AR22: 132074841 | AT22: 11754055 | AU22: 77780568595 | AV22: САП
A23: 1 | B23: 863 Павлодар ТОО «DCG ERTIS» (KIA) | C23: K5 | D23: Prestige | E23: EUS42JG1J | F23: MX16A414BSK045429 | G23: ABP Aurora Black Pearl / Чёрный перламутр | H23: G156 | I23: 2WD | J23: AT | K23: 1975 | L23: 2025 | M23: 863_293012 | N23: 46126 | O23: ЕРЖАН КАРАМЕНДИНОВ | P23: Шаймырза Мадияр Нуржанулы | Q23: 991124350117 | T23: 13990000 | U23: 13990000 | V23: 0 | W23: 0 | X23: 0 | Y23: 769450 | Z23: 769450 | AA23: 3s | AB23: =U23*0.5% -> 69950 | AC23: 0.055 | AD23: =U23*AC23 -> 769450 | AE23: =AD23-V23 -> 769450 | AF23: 6 000 000.00 | AG23: 46129 | AH23: Павлодар | AI23: Кредит | AJ23: Стандартное кредитование | AK23: Altyn Bank | AL23: 84 месяца | AM23: 43 | AN23: 0 | AP23: 0 | AQ23: 0 | AR23: 132075411 | AS23: 196900 | AT23: 11768708 | AU23: 77471912805 | AV23: САП
A24: 1 | B24: 331 Шымкент ТОО «DCG ONTUSTIK» (KIA) | C24: K5 | D24: Prestige | E24: EUS42JG1J | F24: MX16A414BSK045492 | G24: SWP Snow White Pearl / Белый перламутр | H24: G156 | I24: 2WD | J24: AT | K24: 1975 | L24: 2025 | M24: 331_292523 | N24: 46118 | O24: Абылайхан Нагибек | P24: Аширова Гулмира Барзуовна | Q24: 681230400802 | T24: 13990000 | U24: 13990000 | V24: 0 | W24: 0 | X24: 0 | Y24: 769450 | Z24: 769450 | AA24: 3s | AB24: =U24*0.5% -> 69950 | AC24: 0.055 | AD24: =U24*AC24 -> 769450 | AE24: =AD24-V24 -> 769450 | AG24: 46120 | AH24: Шымкент | AI24: Безналичный расчет | AJ24: Безналичный | AK24: Без привлечения кредита | AN24: 0 | AP24: 0 | AQ24: 0 | AR24: 132074716 | AS24: 196900 | AT24: 11774590 | AU24: 77780506870 | AV24: САП
A25: 1 | B25: 371 Астана ТОО «DCG ASTANA» (KIA) | C25: Cerato | D25: Luxe+ | E25: DJS4D261F | F25: MX1F4416BSK004210 | G25: UD Clear White / Белый | H25: G02O | I25: 2WD | J25: AT | K25: 1591 | L25: 2025 | M25: 371_293244 | N25: 46129 | O25: Артур Пак | P25: Жунусов Алихан Жасуланович | Q25: 901226350393 | T25: 10740000 | U25: 10490000 | V25: 0 | W25: 0 | X25: 250000 | Y25: 419600 | Z25: 419600 | AA25: 1s | AB25: =U25*0.5% -> 52450 | AC25: 0.04 | AD25: =U25*AC25 -> 419600 | AE25: =AD25-V25 -> 419600 | AF25: 5 250 000.00 | AG25: 46136 | AH25: Астана | AI25: Кредит | AJ25: Стандартное кредитование | AK25: Евразийский банк | AL25: 84 месяца | AM25: 50 | AN25: 0 | AP25: 0 | AQ25: 0 | AR25: 132075977 | AT25: 11785166 | AU25: 77011057917 | AV25: САП
A26: 1 | B26: 735 Усть-Каменогорск ТОО «DCG VOSTOK» (KIA) | C26: K5 | D26: Luxe | E26: EUS42JG1J | F26: MX16A414BSK045131 | G26: AG2 Graphite Gray / Серый | H26: G155 | J26: AT | K26: 1975 | L26: 2025 | M26: 735_293887 | N26: 46139 | O26: Максим Косихин | P26: Мендыбаева Салтанат Сайлаугазовна | Q26: 780806402789 | T26: 12690000 | U26: 12690000 | V26: 0 | W26: 0 | X26: 0 | Y26: 697950 | Z26: 697950 | AA26: 1s | AB26: =U26*0.5% -> 63450 | AC26: 0.045 | AD26: =U26*AC26 -> 571050 | AE26: =AD26-V26 -> 571050 | AF26: 12 690 000.00 | AG26: 46140 | AH26: Усть-Каменогорск | AI26: Безналичный расчет | AJ26: Безналичный | AK26: Без привлечения кредита | AN26: 0 | AO26: 381 Allur Auto Group KIA | AP26: 0 | AQ26: 0 | AR26: 132076195 | AT26: 11792267 | AU26: 77051205357 | AV26: САП
A27: 1 | B27: 331 Шымкент ТОО «DCG ONTUSTIK» (KIA) | C27: Ceed | D27: Comfort | E27: J7S6D261F | F27: MX1H1516BSK257863 | G27: HW2 Deluxe White / Белый перламутр | H27: S10W | I27: 2WD | J27: AT | K27: 1591 | L27: 2025 | M27: 331_292503 | N27: 46118 | O27: Ернар Жайдарбек | P27: Онласбеков Алмас Атирханович | Q27: 830223302676 | T27: 9690000 | U27: 9690000 | V27: 0 | W27: 0 | X27: 0 | Y27: 436050 | Z27: 436050 | AA27: 3s | AB27: =U27*0.5% -> 48450 | AC27: 0.045 | AD27: =U27*AC27 -> 436050 | AE27: =AD27-V27 -> 436050 | AG27: 46119 | AH27: Шымкент | AI27: Безналичный расчет | AJ27: Безналичный | AK27: Без привлечения кредита | AN27: 0 | AP27: 0 | AQ27: 0 | AR27: 132074728 | AS27: 122900 | AT27: 11802657 | AU27: 77717951777 | AV27: САП
A28: 1 | B28: 735 Усть-Каменогорск ТОО «DCG VOSTOK» (KIA) | C28: Ceed SW | D28: Comfort | E28: J7W5D261F | F28: MX1H4816BSK253924 | G28: HW2 Deluxe White / Белый перламутр | H28: K0OP | I28: 2WD | J28: AT | K28: 1591 | L28: 2025 | M28: 735_293260 | N28: 46129 | O28: Азамат Тоқтарбеков | P28: Әбиев Расул Қырықбайұлы | Q28: 40216550843 | T28: 11240000 | U28: 10990000 | V28: 0 | W28: 0 | X28: 250000 | Y28: 494550 | Z28: 494550 | AA28: 1s | AB28: =U28*0.5% -> 54950 | AC28: 0.045 | AD28: =U28*AC28 -> 494550 | AE28: =AD28-V28 -> 494550 | AF28: 1 273 135.00 | AG28: 46132 | AH28: Усть-Каменогорск | AI28: Кредит | AJ28: Стандартное кредитование | AK28: Банк ЦентрКредит | AL28: 84 месяца | AM28: 40 | AN28: 0 | AP28: 0 | AQ28: 0 | AR28: 132075524 | AS28: 127900 | AT28: 11815914 | AU28: 77476242119 | AV28: САП
A29: 1 | B29: 371 Астана ТОО «DCG ASTANA» (KIA) | C29: Ceed SW | D29: Luxe | E29: J7W5D261F | F29: MX1H5816BSK253985 | G29: 1K Black Pearl / Чёрный перламутр | H29: H33I | I29: 2WD | J29: AT | K29: 1591 | L29: 2025 | M29: 371_292608 | N29: 46119 | O29: Даурен Манкулов | P29: Усенбаев Нуршат Ергешович | Q29: 830807300218 | T29: 11490000 | U29: 11490000 | V29: 0 | W29: 0 | X29: 0 | Y29: 517050 | Z29: 517050 | AA29: 1s | AB29: =U29*0.5% -> 57450 | AC29: 0.045 | AD29: =U29*AC29 -> 517050 | AE29: =AD29-V29 -> 517050 | AF29: 11 490 000.00 | AG29: 46120 | AH29: Астана | AI29: Наличный расчет | AJ29: Наличный расчет | AK29: Без привлечения кредита | AN29: 0 | AP29: 0 | AQ29: 0 | AR29: 132074775 | AT29: 11836538 | AU29: 77788386665 | AV29: САП
A30: 1 | B30: 371 Астана ТОО «DCG ASTANA» (KIA) | C30: Ceed SW | D30: Luxe | E30: J7W5D261F | F30: MX1H5816BSK253620 | G30: USG Yuca Steel Gray/Стальной | H30: H33I | I30: 2WD | J30: AT | K30: 1591 | L30: 2025 | M30: 371_293137 | N30: 46127 | O30: Виктория Чубинец | P30: Жаканов Есбол Еркингалиевич | Q30: 900325301043 | T30: 11490000 | U30: 11490000 | V30: 0 | W30: 0 | X30: 0 | Y30: 517050 | Z30: 517050 | AA30: 1s | AB30: =U30*0.5% -> 57450 | AC30: 0.045 | AD30: =U30*AC30 -> 517050 | AE30: =AD30-V30 -> 517050 | AF30: 2 298 000.00 | AG30: 46134 | AH30: Астана | AI30: Льготный кредит | AJ30: Льготное кредитование | AK30: Halyk Bank | AL30: 84 месяца | AM30: 20 | AN30: 0 | AP30: 0 | AQ30: 0 | AR30: 132075833 | AT30: 11836552 | AU30: 77055550785 | AV30: САП
A31: 1 | B31: 331 Шымкент ТОО «DCG ONTUSTIK» (KIA) | C31: K5 | D31: Tulpar | E31: EUS42JG1J | F31: MX16A414BSK045972 | G31: ABP Aurora Black Pearl / Чёрный перламутр | H31: G174 | I31: 2WD | J31: AT | K31: 0 | L31: 2025 | M31: 331_292850 | N31: 46124 | O31: Нұрсұлтан Көкежан | P31: Жайлымыс Гулвира Қаныбекқызы | Q31: 940821401549 | T31: 13940000 | U31: 13390000 | V31: 0 | W31: 0 | X31: 550000 | Y31: 736450 | Z31: 736450 | AA31: 3s | AB31: =U31*0.5% -> 66950 | AC31: 0.055 | AD31: =U31*AC31 -> 736450 | AE31: =AD31-V31 -> 736450 | AF31: 7 000 000.00 | AG31: 46127 | AH31: Шымкент | AI31: Кредит | AJ31: Стандартное кредитование | AK31: Halyk Bank | AL31: 84 месяца | AM31: 45 | AN31: 0 | AP31: 0 | AQ31: 0 | AR31: 132075245 | AS31: 189900 | AT31: 11869042 | AU31: 77074131020 | AV31: САП
A32: 1 | B32: 331 Шымкент ТОО «DCG ONTUSTIK» (KIA) | C32: K5 | D32: Prestige | E32: EUS42JG1J | F32: MX16A414BSK045862 | G32: AG2 Graphite Gray / Серый | H32: G156 | I32: 2WD | J32: AT | K32: 1975 | L32: 2025 | M32: 331_293905 | N32: 46139 | O32: Арман Сабыров | P32: Алашбаев Барат Мамаханович | Q32: 721027300654 | T32: 13990000 | U32: 13990000 | V32: 0 | W32: 0 | X32: 0 | Y32: 769450 | Z32: 769450 | AA32: 3s | AB32: =U32*0.5% -> 69950 | AC32: 0.055 | AD32: =U32*AC32 -> 769450 | AE32: =AD32-V32 -> 769450 | AF32: 3 990 000.00 | AG32: 46142 | AH32: Шымкент | AI32: Кредит | AJ32: Льготное кредитование | AK32: Halyk Bank | AL32: 84 месяца | AM32: 30 | AN32: 0 | AP32: 0 | AQ32: 0 | AR32: 132076553 | AS32: 196900 | AT32: 11869045 | AU32: 77076554172 | AV32: САП
A33: 1 | B33: 863 Павлодар ТОО «DCG ERTIS» (KIA) | C33: K5 | D33: Luxe | E33: EUS42JG1J | F33: MX16A414BSK046190 | G33: AG2 Graphite Gray / Серый | H33: G155 | J33: AT | K33: 1975 | L33: 2025 | M33: 863_292937 | N33: 46125 | O33: ЕРЖАН КАРАМЕНДИНОВ | P33: Мусабеков Ринат Серикказыевич | Q33: 820411301112 | T33: 12690000 | U33: 12690000 | V33: 0 | W33: 0 | X33: 0 | Y33: 697950 | Z33: 697950 | AA33: 3s | AB33: =U33*0.5% -> 63450 | AC33: 0.055 | AD33: =U33*AC33 -> 697950 | AE33: =AD33-V33 -> 697950 | AF33: 6 345 000.00 | AG33: 46140 | AH33: Павлодар | AI33: Кредит | AJ33: Стандартное кредитование | AK33: Halyk Bank | AL33: 36 месяцев | AM33: 50 | AN33: 0 | AP33: 0 | AQ33: 0 | AR33: 132076234 | AT33: 11869205 | AU33: 77054440001 | AV33: САП
A34: 1 | B34: 1151 Алматы ТОО «DCG Qulja» (KIA) | C34: K5 | D34: Tulpar | E34: EUS42JG1J | F34: MX16A414BSK046128 | G34: SWP Snow White Pearl / Белый перламутр | H34: G176 | I34: 2WD | J34: AT | K34: 1975 | L34: 2025 | M34: 1151_292374 | N34: 46118 | O34: Магилан Махамет | P34: АХИЛЬГОВ ИЛЬЯС СУЛТАНОВИЧ | Q34: 891019302353 | T34: 13390000 | U34: 13390000 | V34: 0 | W34: 0 | X34: 0 | Y34: 791450 | Z34: 791450 | AA34: 3s | AB34: =U34*0.5% -> 66950 | AC34: 0.055 | AD34: =U34*AC34 -> 736450 | AE34: =AD34-V34 -> 736450 | AF34: 100 000.00 | AG34: 46136 | AH34: Алматы | AI34: Наличный расчет | AJ34: Наличный расчет | AK34: Без привлечения кредита | AN34: 0 | AP34: 0 | AQ34: 0 | AR34: 132075986 | AS34: 189900 | AT34: 11870591 | AU34: 77017666627 | AV34: САП
A35: 1 | B35: 735 Усть-Каменогорск ТОО «DCG VOSTOK» (KIA) | C35: K5 | D35: Tulpar | E35: EUS42JG1J | F35: MX16A414BSK045967 | G35: SWP Snow White Pearl / Белый перламутр | H35: G174 | I35: 2WD | J35: AT | K35: 0 | L35: 2025 | M35: 735_292362 | N35: 46116 | O35: Дарын Әмірбеков | P35: Бектибаев Саяхат Аитмухаметулы | Q35: 810108300402 | T35: 13640000 | U35: 14390000 | V35: 0 | W35: 1000000 | X35: 250000 | Y35: 791450 | Z35: 791450 | AA35: 1s | AB35: =U35*0.5% -> 71950 | AC35: 0.045 | AD35: =U35*AC35 -> 647550 | AE35: =AD35-V35 -> 647550 | AF35: 2 728 000.00 | AG35: 46120 | AH35: Усть-Каменогорск | AI35: Кредит | AJ35: Стандартное кредитование | AK35: Halyk Bank | AL35: 84 месяца | AM35: 20 | AN35: 0 | AP35: 0 | AQ35: 0 | AR35: 132074782 | AS35: 189900 | AT35: 11871863 | AU35: 77055321642 | AV35: САП
A36: 1 | B36: 1069 Актау TOO «DCG Aktau» (KIA) | C36: Sorento 2025 | D36: Tulpar | E36: GZW7L961G | F36: MX1RH81DDSK366026 | G36: BN4 New Gray / Серый | H36: G2YU | I36: 4WD | J36: AT | K36: 2497 | L36: 2025 | M36: 1069_293640 | N36: 46135 | O36: Нурали Садыбаев | P36: Хайрмеденов Кайрбек Ушкишбекович | Q36: 850928302197 | T36: 18990000 | U36: 18990000 | V36: 0 | W36: 0 | X36: 0 | Y36: 1044450 | Z36: 1044450 | AA36: 3s | AB36: =U36*0.5% -> 94950 | AC36: 0.055 | AD36: =U36*AC36 -> 1044450 | AE36: =AD36-V36 -> 1044450 | AF36: 9 500 000.00 | AG36: 46140 | AH36: Актау | AI36: Кредит | AJ36: Стандартное кредитование | AK36: Halyk Bank | AL36: 36 месяцев | AM36: 50 | AN36: 0 | AP36: 0 | AQ36: 0 | AR36: 132076218 | AS36: 241900 | AT36: 11896502 | AU36: 77073996969 | AV36: САП
A37: 1 | B37: 1069 Актау TOO «DCG Aktau» (KIA) | C37: Cerato | D37: Luxe+ | E37: DJS4D261F | F37: MX1F4416BSK005443 | G37: UD Clear White / Белый | H37: G02O | I37: 2WD | J37: AT | K37: 1591 | L37: 2025 | M37: 1069_293140 | N37: 46127 | O37: Тимур Нурибаев | P37: Сматов Исатай Маратұлы | Q37: 780712300160 | T37: 10490000 | U37: 10490000 | V37: 0 | W37: 0 | X37: 0 | Y37: 419600 | Z37: 419600 | AA37: 3s | AB37: =U37*0.5% -> 52450 | AC37: 0.04 | AD37: =U37*AC37 -> 419600 | AE37: =AD37-V37 -> 419600 | AF37: 2 098 000.00 | AG37: 46133 | AH37: Актау | AI37: Льготный кредит | AJ37: Льготное кредитование | AK37: Halyk Bank | AL37: 84 месяца | AM37: 20 | AN37: 0 | AP37: 0 | AQ37: 0 | AR37: 132075606 | AT37: 11896509 | AU37: 77022201191 | AV37: САП
A38: 1 | B38: 331 Шымкент ТОО «DCG ONTUSTIK» (KIA) | C38: Soul | D38: Style | E38: SKW52G61V | F38: MX1J381UESK272812 | G38: AH1 Clear White / Inferno Red / Белый с красной крышей | H38: G906 | I38: 2WD | J38: AT | K38: 1999 | L38: 2025 | M38: 331_292740 | N38: 46121 | O38: Абдукарим Абдукаим | P38: Тулеумбетов Нурсултан Махмутович | Q38: 891005302357 | T38: 12990000 | U38: 12990000 | V38: 0 | W38: 0 | X38: 0 | Y38: 584550 | Z38: 584550 | AA38: 3s | AB38: =U38*0.5% -> 64950 | AC38: 0.045 | AD38: =U38*AC38 -> 584550 | AE38: =AD38-V38 -> 584550 | AF38: 2 990 000.00 | AG38: 46139 | AH38: Шымкент | AI38: Кредит | AJ38: Льготное кредитование | AK38: Halyk Bank | AL38: 84 месяца | AM38: 20 | AN38: 0 | AP38: 0 | AQ38: 0 | AR38: 132076108 | AS38: 149900 | AT38: 11898117 | AU38: 77710180066 | AV38: САП
A39: 1 | B39: 1069 Актау TOO «DCG Aktau» (KIA) | C39: Sorento 2025 | D39: Tulpar | E39: GZW7L961G | F39: MX1RH81DDSK370432 | G39: SWP Snow White Pearl / Белый перламутр | H39: G2YU | I39: 4WD | J39: AT | K39: 2497 | L39: 2025 | M39: 1069_293047 | N39: 46126 | O39: Тимур Нурибаев | P39: Конусова Гулшат Жайылгановна | Q39: 930419000032 | T39: 18990000 | U39: 18990000 | V39: 0 | W39: 0 | X39: 0 | Y39: 1044450 | Z39: 1044450 | AA39: 3s | AB39: =U39*0.5% -> 94950 | AC39: 0.045 | AD39: =U39*AC39 -> 854550 | AE39: =AD39-V39 -> 854550 | AF39: 18 990 000.00 | AG39: 46129 | AH39: Актау | AI39: Наличный расчет | AJ39: Наличный расчет | AK39: Без привлечения кредита | AN39: 0 | AP39: 0 | AQ39: 0 | AR39: 132075442 | AS39: 241900 | AT39: 11931916 | AU39: 77020617288 | AV39: САП
A40: 1 | B40: 363 Алматы ТОО «DCG ALMATY» (KIA) | C40: Seltos | D40: Style | E40: THW52G61Q | F40: MX1ER81AKTK833516 | G40: FSB Modern Black / Черный | H40: G0DK | I40: 4WD | J40: CVT | K40: 1999 | L40: 2025 | M40: 363_294076 | N40: 46141 | O40: Даур Құттыбай | P40: Максимова Ақбота Максимқызы | Q40: 920705401673 | T40: 13490000 | U40: 13490000 | V40: 0 | W40: 0 | X40: 0 | Y40: 607050 | Z40: 607050 | AA40: 1s | AB40: =U40*0.5% -> 67450 | AC40: 0.045 | AD40: =U40*AC40 -> 607050 | AE40: =AD40-V40 -> 607050 | AF40: 3 304 000.00 | AG40: 46142 | AH40: Алматы | AI40: Кредит | AJ40: Стандартное кредитование | AK40: Halyk Bank | AL40: 84 месяца | AM40: 10 | AN40: 0 | AP40: 0 | AQ40: 0 | AR40: 132076501 | AS40: 176900 | AT40: 11944944 | AU40: 77470647847 | AV40: САП
...

Sheet Киа
A1: Кол-во | B1: Название ДЦ | C1: Модель KIA | D1: Комплектация KIA | E1: Код модели KIA | F1: VIN KZ | G1: Цвет УС KIA | H1: Модификация | I1: Привод | J1: КПП | K1: Объем двигателя, см3 | L1: Год выпуска | M1: Номер договора | N1: Дата договора | O1: Ответственный | P1: ФИО | Q1: Контакт: ИИН/БИН | R1: Компания: Название компании | S1: Компания: БИН | T1: Цена реализации | U1: Рекомендуемая розничная цена | V1: Сумма скидки | W1: Скидка дистрибуции | X1: Стоимость доп. оборудования | Y1: Максимальное вознаграждение дилера | Z1: Вознаграждение без скидки | AA1: 1s/3s | AB1: % | AC1: Маржа | AD1: Маржа после скидок | AE1: Сумма предоплаты, тенге | AF1: Дата подписания акта п/п | AG1: Место реализации (город) | AH1: !Тип продажи а/м | AI1: Способ приобретения | AJ1: Кредит в банке | AK1: Срок кредита в месяцах | AL1: Размер первоначального взноса по кредиту (В процентах) | AM1: Число попаданий на замечания | AN1: Название ДЦ. откуда забрали машину | AO1: Вознаграждение дилера (за перемещённую машину) | AP1: Компенсация дилера | AQ1: Номер карты Технической поддержки Litro | AR1: Дополнительная компенсация дилера | AS1: ID | AT1: Номер телефона | AU1: Завод производитель
A2: 1 | B2: 331 Шымкент ТОО «DCG ONTUSTIK» (KIA) | C2: Seltos | D2: Style | E2: THW52G61Q | F2: MX1ER81AKRK673769 | G2: B3A Neptune Blue / Синий | H2: G0BQ | I2: 4WD | J2: AT | K2: 1999 | L2: 2024 | M2: 331_292944 | N2: 46125 | O2: Ернар Жайдарбек | P2: Селифанова Инна Викторовна | Q2: 780928402396 | T2: 12990000 | U2: 12990000 | V2: 0 | W2: 0 | X2: 0 | Y2: 0 | Z2: 0 | AA2: 3s | AB2: 0.045 | AC2: =U2*AB2 -> 584550 | AD2: =AC2-V2 -> 584550 | AF2: 46126.917 | AG2: Шымкент | AH2: Безналичный расчет | AI2: Безналичный | AJ2: Без привлечения кредита | AM2: 0 | AO2: 0 | AP2: 0 | AQ2: 132075139 | AS2: 10448600 | AT2: 77015603204 | AU2: САП
A3: 1 | B3: 331 Шымкент ТОО «DCG ONTUSTIK» (KIA) | C3: Sportage | D3: X-Line+ | E3: GYWDL9A1K | F3: MX1PX81FDRK011802 | G3: UD Clear White / Белый | H3: H0D1 | I3: 4WD | J3: AT | K3: 2497 | L3: 2024 | M3: 331_294098 | N3: 46141 | O3: Абдукарим Абдукаим | P3: Ройтман Рустам | Q3: 760211302101 | T3: 15784000 | U3: 16190000 | V3: 216000 | W3: 190000 | X3: 0 | Y3: 0 | Z3: -216000 | AA3: 3s | AB3: 0.055 | AC3: =U3*AB3 -> 890450 | AD3: =AC3-V3 -> 674450 | AF3: 46142 | AG3: Шымкент | AH3: Безналичный расчет | AI3: Безналичный | AJ3: Без привлечения кредита | AM3: 0 | AO3: 0 | AP3: 0 | AQ3: 132076748 | AS3: 10448618 | AT3: 77077000991 | AU3: САП
A4: 1 | B4: 331 Шымкент ТОО «DCG ONTUSTIK» (KIA) | C4: Ceed | D4: Luxe | E4: J7S6D261F | F4: MX1H2516BSK236164 | G4: H8G Penta Metal / Серый | H4: D2U5 | I4: 2WD | J4: AT | K4: 0 | L4: 2024 | M4: 331_292604 | N4: 46119 | O4: Жандаулет Жұмалиев | P4: Кредина Юлия Александровна | Q4: 871006401238 | T4: 8890000 | U4: 8890000 | V4: 0 | W4: 0 | X4: 0 | Y4: 0 | Z4: 0 | AA4: 3s | AB4: 0.045 | AC4: =U4*AB4 -> 400050 | AD4: =AC4-V4 -> 400050 | AF4: 46133 | AG4: Шымкент | AH4: Безналичный расчет | AI4: Безналичный | AJ4: Без привлечения кредита | AM4: 0 | AO4: 0 | AP4: 0 | AQ4: 132075639 | AR4: 129900 | AS4: 10685796 | AT4: 77058500030 | AU4: САП
A5: 1 | B5: 331 Шымкент ТОО «DCG ONTUSTIK» (KIA) | C5: Ceed | D5: Comfort | E5: J7S6D261F | F5: MX1H1516BSK239964 | G5: WD Casa White / Белый | H5: S10W | I5: 2WD | J5: AT | K5: 1591 | L5: 2025 | M5: 331_292796 | N5: 46122 | O5: Қаныбек Рахманәлі | P5: Утегенова Кулзат Шаймовна | Q5: 670912402356 | T5: 9690000 | U5: 9690000 | V5: 0 | W5: 0 | X5: 0 | Y5: 436050 | Z5: 436050 | AA5: 3s | AB5: 0.045 | AC5: =U5*AB5 -> 436050 | AD5: =AC5-V5 -> 436050 | AE5: 2 590 000.00 | AF5: 46128 | AG5: Шымкент | AH5: Кредит | AI5: Льготное кредитование | AJ5: Halyk Bank | AK5: 84 месяца | AL5: 20 | AM5: 0 | AO5: 0 | AP5: 0 | AQ5: 132075335 | AR5: 122900 | AS5: 11010655 | AT5: 77710199162 | AU5: САП
A6: 1 | B6: 331 Шымкент ТОО «DCG ONTUSTIK» (KIA) | C6: Seltos | D6: Luxe | E6: THW52G61V | F6: MX1ER81AESK765870 | G6: KLG Steel Gray / Стальной | H6: G0BM | I6: 2WD | J6: AT | K6: 1999 | L6: 2025 | M6: 331_293611 | N6: 46134 | O6: Абылайхан Нагибек | P6: Файзиев Елнур Хамзаевич | Q6: 840317301462 | T6: 11990000 | U6: 11990000 | V6: 0 | W6: 0 | X6: 0 | Y6: 634050 | Z6: 634050 | AA6: 3s | AB6: 0.045 | AC6: =U6*AB6 -> 539550 | AD6: =AC6-V6 -> 539550 | AF6: 46135 | AG6: Шымкент | AH6: Безналичный расчет | AI6: Безналичный | AJ6: Без привлечения кредита | AM6: 0 | AO6: 0 | AP6: 0 | AQ6: 132075931 | AR6: 153900 | AS6: 11037821 | AT6: 77077064040 | AU6: САП
A7: 1 | B7: 863 Павлодар ТОО «DCG ERTIS» (KIA) | C7: Ceed | D7: Luxe | E7: J7S6D261F | F7: MX1H2516BSK247884 | G7: H8G Penta Metal / Серый | H7: D2U5 | I7: 2WD | J7: AT | K7: 0 | L7: 2025 | M7: 863_293026 | N7: 46126 | O7: ЕРЖАН КАРАМЕНДИНОВ | P7: Толеу Олжас Жантасулы | Q7: 930224350672 | T7: 10690000 | U7: 10690000 | V7: 0 | W7: 0 | X7: 0 | Y7: 481050 | Z7: 481050 | AA7: 3s | AB7: 0.045 | AC7: =U7*AB7 -> 481050 | AD7: =AC7-V7 -> 481050 | AE7: 10 690 000.00 | AF7: 46126 | AG7: Павлодар | AH7: Наличный расчет | AI7: Наличный расчет | AJ7: Без привлечения кредита | AL7: 100 | AM7: 0 | AO7: 0 | AP7: 0 | AQ7: 132075156 | AR7: 129900 | AS7: 11090787 | AT7: 77471136340 | AU7: САП
A8: 1 | B8: 363 Алматы ТОО «DCG ALMATY» (KIA) | C8: Ceed SW | D8: Comfort | E8: J7W5D261F | F8: MX1H4816BSK239650 | G8: HW2 Deluxe White / Белый перламутр | H8: K0OP | I8: 2WD | J8: AT | K8: 1591 | L8: 2025 | M8: 363_292472 | N8: 46118 | O8: Бахытжан Смагулов | P8: Нурмухамет Ербол | Q8: 890524301239 | T8: 10990000 | U8: 10990000 | V8: 0 | W8: 0 | X8: 0 | Y8: 494550 | Z8: 494550 | AA8: 1s | AB8: 0.045 | AC8: =U8*AB8 -> 494550 | AD8: =AC8-V8 -> 494550 | AE8: 10 990 000.00 | AF8: 46120 | AG8: Алматы | AH8: Наличный расчет | AI8: Наличный расчет | AJ8: Без привлечения кредита | AM8: 0 | AO8: 0 | AP8: 0 | AQ8: 132074818 | AR8: 127900 | AS8: 11583852 | AT8: 77777765777 | AU8: САП
A9: 1 | B9: 331 Шымкент ТОО «DCG ONTUSTIK» (KIA) | C9: Seltos | D9: Comfort | E9: THW52G61V | F9: MX1EP81AESK776725 | G9: KDG Gravity Gray / Серый | H9: D395 | I9: 2WD | J9: AT | K9: 1999 | L9: 2025 | M9: 331_294107 | N9: 46141 | O9: Арман Сабыров | P9: Рахимжанов Булат Мырзахметович | Q9: 680127302453 | T9: 10990000 | U9: 10990000 | V9: 0 | W9: 0 | X9: 0 | Y9: 494550 | Z9: 494550 | AA9: 3s | AB9: 0.045 | AC9: =U9*AB9 -> 494550 | AD9: =AC9-V9 -> 494550 | AE9: 2 198 000.00 | AF9: 46142 | AG9: Шымкент | AH9: Кредит | AI9: Стандартное кредитование | AJ9: Halyk Bank | AK9: 84 месяца | AL9: 20 | AM9: 0 | AN9: 215 Шымкент TOO «NOMAD MOTORS SHYM» (KIA) | AO9: 0 | AP9: 0 | AQ9: 132076704 | AR9: 145900 | AS9: 11608275 | AT9: 77754060101 | AU9: САП
A10: 1 | B10: 331 Шымкент ТОО «DCG ONTUSTIK» (KIA) | C10: Sorento 2025 | D10: Comfort | E10: GZW5L961G | F10: MX1RH81DDSK343433 | G10: AGT Graphite Gray / Серый | H10: G2IF | I10: 4WD | J10: AT | K10: 2497 | L10: 2025 | M10: 331_292593 | N10: 46119 | O10: Нұрсұлтан Көкежан | P10: Сахыбекова Айнур Жаксылыковна | Q10: 760702400654 | T10: 17240000 | U10: 16990000 | V10: 0 | W10: 0 | X10: 250000 | Y10: 934450 | Z10: 934450 | AA10: 3s | AB10: 0.045 | AC10: =U10*AB10 -> 764550 | AD10: =AC10-V10 -> 764550 | AE10: 3 000 000.00 | AF10: 46127 | AG10: Шымкент | AH10: Кредит | AI10: Стандартное кредитование | AJ10: Банк ЦентрКредит | AK10: 84 месяца | AL10: 20 | AM10: 0 | AN10: 365 Тараз ТОО «DCGTARAZ» (KIA) | AO10: 0 | AP10: 0 | AR10: 216900 | AS10: 11608558 | AT10: 77073589208 | AU10: САП
A11: 1 | B11: 331 Шымкент ТОО «DCG ONTUSTIK» (KIA) | C11: Cerato | D11: Comfort | E11: DJS4D261F | F11: MX1F3416BSK003073 | G11: KLG Steel Gray / Стальной | H11: D0A6 | I11: 2WD | J11: AT | K11: 1591 | L11: 2025 | M11: 331_292471 | N11: 46118 | O11: Абылайхан Нагибек | P11: Жонеуов Канатбек Жаксылыкбаевич | Q11: 851103301572 | T11: 10310000 | U11: 9990000 | V11: 0 | W11: 0 | X11: 320000 | Y11: 399600 | Z11: 399600 | AA11: 3s | AB11: 0.04 | AC11: =U11*AB11 -> 399600 | AD11: =AC11-V11 -> 399600 | AE11: 1 031 000.00 | AF11: 46120 | AG11: Шымкент | AH11: Кредит | AI11: Стандартное кредитование | AJ11: Банк ЦентрКредит | AK11: 84 месяца | AL11: 10 | AM11: 0 | AO11: 0 | AP11: 0 | AQ11: 132074816 | AS11: 11608876 | AT11: 77076840585 | AU11: САП
A12: 1 | B12: 735 Усть-Каменогорск ТОО «DCG VOSTOK» (KIA) | C12: K5 | D12: Prestige | E12: EUS42JG1J | F12: MX16A414BSK044694 | G12: SWP Snow White Pearl / Белый перламутр | H12: G156 | I12: 2WD | J12: AT | K12: 1975 | L12: 2025 | M12: 735_293367 | N12: 46131 | O12: Дарын Әмірбеков | P12: Болатов Алмас Болатұлы | Q12: 950309351468 | T12: 14240000 | U12: 13990000 | V12: 0 | W12: 0 | X12: 250000 | Y12: 769450 | Z12: 769450 | AA12: 1s | AB12: 0.045 | AC12: =U12*AB12 -> 629550 | AD12: =AC12-V12 -> 629550 | AE12: 2 848 000.00 | AF12: 46135 | AG12: Усть-Каменогорск | AH12: Кредит | AI12: Стандартное кредитование | AJ12: Halyk Bank | AK12: 84 месяца | AL12: 20 | AM12: 0 | AO12: 0 | AP12: 0 | AQ12: 132075936 | AR12: 196900 | AS12: 11620509 | AT12: 77027679437 | AU12: САП
A13: 1 | B13: 365 Тараз ТОО «DCGTARAZ» (KIA) | C13: Ceed | D13: Comfort | E13: J7S6D261F | F13: MX1H1516BSK253995 | G13: H8G Penta Metal / Серый | H13: S10W | I13: 2WD | J13: AT | K13: 1591 | L13: 2025 | M13: 365_292181 | N13: 46112 | O13: Тұрар Жеңіс | P13: Сарбаев Ескендір Жұмабайұлы | Q13: 940124301602 | T13: 10240000 | U13: 9690000 | V13: 0 | W13: 0 | X13: 550000 | Y13: 436050 | Z13: 436050 | AA13: 1s | AB13: 0.045 | AC13: =U13*AB13 -> 436050 | AD13: =AC13-V13 -> 436050 | AE13: 3 500 000.00 | AF13: 46119 | AG13: Тараз | AH13: Кредит | AI13: Стандартное кредитование | AJ13: Евразийский банк | AK13: 84 месяца | AL13: 35 | AM13: 0 | AN13: 331 Шымкент ТОО «DCG ONTUSTIK» (KIA) | AO13: 0 | AP13: 0 | AQ13: 132074730 | AR13: 122900 | AS13: 11704211 | AT13: 77075958349 | AU13: САП
A14: 1 | B14: 863 Павлодар ТОО «DCG ERTIS» (KIA) | C14: Seltos | D14: Luxe | E14: THW52G61V | F14: MX1ER81AESK791864 | G14: KDG Gravity Gray / Серый | H14: G0BM | I14: 2WD | J14: AT | K14: 1999 | L14: 2025 | M14: 863_293237 | N14: 46129 | O14: Алишер Сериков | P14: Сон Виталий Валерьевич | Q14: 820320350314 | T14: 11990000 | U14: 11990000 | V14: 0 | W14: 0 | X14: 0 | Y14: 634050 | Z14: 634050 | AA14: 3s | AB14: 0.045 | AC14: =U14*AB14 -> 539550 | AD14: =AC14-V14 -> 539550 | AE14: 2 398 000.00 | AF14: 46135 | AG14: Павлодар | AH14: Кредит | AI14: Льготное кредитование | AJ14: Halyk Bank | AK14: 84 месяца | AL14: 20 | AM14: 0 | AO14: 0 | AP14: 0 | AQ14: 132075928 | AR14: 153900 | AS14: 11720930 | AT14: 77015520128 | AU14: САП
A15: 1 | B15: 1151 Алматы ТОО «DCG Qulja» (KIA) | C15: Seltos | D15: Luxe | E15: THW52G61V | F15: MX1ER81AESK792400 | G15: SWP Snow White Pearl / Белый перламутр | H15: G0BM | I15: 2WD | J15: AT | K15: 1999 | L15: 2025 | M15: 1151_293792 | N15: 46140 | O15: Мади Мынбаев | P15: БЕРДЫБАЕВ МУРАТ ЕГИЗБАЕВИЧ | Q15: 670608301765 | T15: 11990000 | U15: 11990000 | V15: 0 | W15: 0 | X15: 0 | Y15: 634050 | Z15: 634050 | AA15: 3s | AB15: 0.045 | AC15: =U15*AB15 -> 539550 | AD15: =AC15-V15 -> 539550 | AF15: 46142 | AG15: Алматы | AH15: Наличный расчет | AI15: Наличный расчет | AJ15: Без привлечения кредита | AM15: 0 | AN15: 331 Шымкент ТОО «DCG ONTUSTIK» (KIA) | AO15: 0 | AP15: 0 | AR15: 153900 | AS15: 11720969 | AT15: 77025388525 | AU15: САП
A16: 1 | B16: 365 Тараз ТОО «DCGTARAZ» (KIA) | C16: Seltos | D16: Luxe | E16: THW52G61V | F16: MX1ER81AESK790601 | G16: FSB Modern Black / Черный | H16: G0BM | I16: 2WD | J16: AT | K16: 1999 | L16: 2025 | M16: 365_293027 | N16: 46126 | O16: Сұлтан Пойызбаев | P16: Мамышева Бекзат Бауржановна | Q16: 861106400453 | T16: 11990000 | U16: 11990000 | V16: 0 | W16: 0 | X16: 0 | Y16: 634050 | Z16: 634050 | AA16: 1s | AB16: 0.045 | AC16: =U16*AB16 -> 539550 | AD16: =AC16-V16 -> 539550 | AE16: 2 398 000.00 | AF16: 46133 | AG16: Тараз | AH16: Кредит | AI16: Льготное кредитование | AJ16: Halyk Bank | AK16: 84 месяца | AL16: 20 | AM16: 0 | AO16: 0 | AP16: 0 | AQ16: 132075670 | AR16: 153900 | AS16: 11721007 | AT16: 77011301532 | AU16: САП
A17: 1 | B17: 1151 Алматы ТОО «DCG Qulja» (KIA) | C17: K5 | D17: Prestige | E17: EUS42JG1J | F17: MX16A414BSK045226 | G17: AG2 Graphite Gray / Серый | H17: G156 | I17: 2WD | J17: AT | K17: 1975 | L17: 2025 | M17: 1151_292671 | N17: 46120 | O17: НУРСУЛТАН КУРПЕТАЕВ | P17: Елюбаев Асхат Болатович | Q17: 931031300644 | T17: 14390000 | U17: 13990000 | V17: 0 | W17: 0 | X17: 400000 | Y17: 769450 | Z17: 769450 | AA17: 3s | AB17: 0.055 | AC17: =U17*AB17 -> 769450 | AD17: =AC17-V17 -> 769450 | AE17: 1 439 000.00 | AF17: 46127 | AG17: Алматы | AH17: Кредит | AI17: Льготное кредитование | AJ17: Банк ЦентрКредит | AK17: 84 месяца | AL17: 10 | AM17: 0 | AN17: 343 Талдыкорган ТОО «Taldykorgan Auto Group» (KIA) | AO17: 0 | AP17: 0 | AQ17: 132075227 | AR17: 196900 | AS17: 11722414 | AT17: 77017227200 | AU17: САП
A18: 1 | B18: 863 Павлодар ТОО «DCG ERTIS» (KIA) | C18: K5 | D18: Prestige | E18: EUS42JG1J | F18: MX16A414BSK045214 | G18: AG2 Graphite Gray / Серый | H18: G156 | I18: 2WD | J18: AT | K18: 1975 | L18: 2025 | M18: 863_293722 | N18: 46136 | O18: КАНАТ АЛЬЖАНОВ | P18: Сатвалдинов Айтуган Закирьянович | Q18: 660124300308 | T18: 13990000 | U18: 13990000 | V18: 0 | W18: 0 | X18: 0 | Y18: 769450 | Z18: 769450 | AA18: 3s | AB18: 0.055 | AC18: =U18*AB18 -> 769450 | AD18: =AC18-V18 -> 769450 | AE18: 11 000 000.00 | AF18: 46142 | AG18: Павлодар | AH18: Кредит | AI18: Стандартное кредитование | AJ18: Банк ЦентрКредит | AK18: 36 месяцев | AL18: 79 | AM18: 0 | AO18: 0 | AP18: 0 | AQ18: 132076523 | AR18: 196900 | AS18: 11724906 | AT18: 77778640891 | AU18: САП
A19: 1 | B19: 1151 Алматы ТОО «DCG Qulja» (KIA) | C19: Sportage | D19: Luxe | E19: GYWD2J61G | F19: MX1PV81DDSK016882 | G19: FSB Modern Black / Черный | H19: G0P1 | I19: 4WD | J19: AT | K19: 1999 | L19: 2025 | M19: 1151_293318 | N19: 46132 | O19: Дайана Калиаскар | P19: ЕРБОЛАТОВА ДАНА РИШАДОВНА | Q19: 960516450532 | T19: 13490000 | U19: 13490000 | V19: 0 | W19: 0 | X19: 0 | Y19: 741950 | Z19: 741950 | AA19: 3s | AB19: 0.055 | AC19: =U19*AB19 -> 741950 | AD19: =AC19-V19 -> 741950 | AE19: 2 690 000.00 | AF19: 46139 | AG19: Алматы | AH19: Льготный кредит | AI19: Льготное кредитование | AJ19: Банк ЦентрКредит | AK19: 84 месяца | AL19: 19 | AM19: 0 | AN19: 363 Алматы ТОО «DCG ALMATY» (KIA) | AO19: 0 | AP19: 0 | AQ19: 132076104 | AR19: 181900 | AS19: 11740393 | AT19: 77054991469 | AU19: САП
A20: 1 | B20: 371 Астана ТОО «DCG ASTANA» (KIA) | C20: K5 | D20: Prestige | E20: EUS42JG1J | F20: MX16A414BSK045168 | G20: ABP Aurora Black Pearl / Чёрный перламутр | H20: G156 | I20: 2WD | J20: AT | K20: 1975 | L20: 2025 | M20: 371_292248 | N20: 46114 | O20: Даурен Манкулов | P20: Музафаров Дархан Шарафиденович | Q20: 920708350552 | T20: 13990000 | U20: 13990000 | V20: 0 | W20: 0 | X20: 0 | Y20: 769450 | Z20: 769450 | AA20: 1s | AB20: 0.045 | AC20: =U20*AB20 -> 629550 | AD20: =AC20-V20 -> 629550 | AE20: 7 000 000.00 | AF20: 46125 | AG20: Астана | AH20: Кредит | AI20: Стандартное кредитование | AJ20: Береке Банк | AK20: 84 месяца | AL20: 50 | AM20: 0 | AO20: 0 | AP20: 0 | AQ20: 132075060 | AR20: 196900 | AS20: 11741552 | AT20: 77055882200 | AU20: САП
A21: 1 | B21: 371 Астана ТОО «DCG ASTANA» (KIA) | C21: Cerato | D21: Luxe+ | E21: DJS4D261F | F21: MX1F4416BSK003629 | G21: UD Clear White / Белый | H21: G02O | I21: 2WD | J21: AT | K21: 1591 | L21: 2025 | M21: 371_292337 | N21: 46116 | O21: Жансерик Туркменов | P21: Негделхан Макпал | Q21: 900313451195 | T21: 10490000 | U21: 10490000 | V21: 0 | W21: 0 | X21: 0 | Y21: 419600 | Z21: 419600 | AA21: 1s | AB21: 0.04 | AC21: =U21*AB21 -> 419600 | AD21: =AC21-V21 -> 419600 | AE21: 7 394 228.00 | AF21: 46119 | AG21: Астана | AH21: Кредит | AI21: Стандартное кредитование | AJ21: Банк ЦентрКредит | AK21: 84 месяца | AL21: 75 | AM21: 0 | AO21: 0 | AP21: 0 | AQ21: 132074721 | AS21: 11748607 | AT21: 77752940222 | AU21: САП
A22: 1 | B22: 331 Шымкент ТОО «DCG ONTUSTIK» (KIA) | C22: Cerato | D22: Comfort | E22: DJS4D261F | F22: MX1F3416BSK003954 | G22: KLG Steel Gray / Стальной | H22: D0A6 | I22: 2WD | J22: AT | K22: 1591 | L22: 2025 | M22: 331_291802 | N22: 46109 | O22: Арман Сабыров | P22: Усманов Максат Заркинович | Q22: 850818303157 | T22: 10540000 | U22: 9990000 | V22: 0 | W22: 0 | X22: 550000 | Y22: 399600 | Z22: 399600 | AA22: 3s | AB22: 0.04 | AC22: =U22*AB22 -> 399600 | AD22: =AC22-V22 -> 399600 | AE22: 2 000 000.00 | AF22: 46120 | AG22: Шымкент | AH22: Кредит | AI22: Стандартное кредитование | AJ22: МФО Sapa Digital Finance | AK22: 84 месяца | AL22: 10 | AM22: 0 | AN22: 215 Шымкент TOO «NOMAD MOTORS SHYM» (KIA) | AO22: 0 | AP22: 0 | AQ22: 132074841 | AS22: 11754055 | AT22: 77780568595 | AU22: САП
A23: 1 | B23: 863 Павлодар ТОО «DCG ERTIS» (KIA) | C23: K5 | D23: Prestige | E23: EUS42JG1J | F23: MX16A414BSK045429 | G23: ABP Aurora Black Pearl / Чёрный перламутр | H23: G156 | I23: 2WD | J23: AT | K23: 1975 | L23: 2025 | M23: 863_293012 | N23: 46126 | O23: ЕРЖАН КАРАМЕНДИНОВ | P23: Шаймырза Мадияр Нуржанулы | Q23: 991124350117 | T23: 13990000 | U23: 13990000 | V23: 0 | W23: 0 | X23: 0 | Y23: 769450 | Z23: 769450 | AA23: 3s | AB23: 0.055 | AC23: =U23*AB23 -> 769450 | AD23: =AC23-V23 -> 769450 | AE23: 6 000 000.00 | AF23: 46129 | AG23: Павлодар | AH23: Кредит | AI23: Стандартное кредитование | AJ23: Altyn Bank | AK23: 84 месяца | AL23: 43 | AM23: 0 | AO23: 0 | AP23: 0 | AQ23: 132075411 | AR23: 196900 | AS23: 11768708 | AT23: 77471912805 | AU23: САП
A24: 1 | B24: 331 Шымкент ТОО «DCG ONTUSTIK» (KIA) | C24: K5 | D24: Prestige | E24: EUS42JG1J | F24: MX16A414BSK045492 | G24: SWP Snow White Pearl / Белый перламутр | H24: G156 | I24: 2WD | J24: AT | K24: 1975 | L24: 2025 | M24: 331_292523 | N24: 46118 | O24: Абылайхан Нагибек | P24: Аширова Гулмира Барзуовна | Q24: 681230400802 | T24: 13990000 | U24: 13990000 | V24: 0 | W24: 0 | X24: 0 | Y24: 769450 | Z24: 769450 | AA24: 3s | AB24: 0.055 | AC24: =U24*AB24 -> 769450 | AD24: =AC24-V24 -> 769450 | AF24: 46120 | AG24: Шымкент | AH24: Безналичный расчет | AI24: Безналичный | AJ24: Без привлечения кредита | AM24: 0 | AO24: 0 | AP24: 0 | AQ24: 132074716 | AR24: 196900 | AS24: 11774590 | AT24: 77780506870 | AU24: САП
A25: 1 | B25: 371 Астана ТОО «DCG ASTANA» (KIA) | C25: Cerato | D25: Luxe+ | E25: DJS4D261F | F25: MX1F4416BSK004210 | G25: UD Clear White / Белый | H25: G02O | I25: 2WD | J25: AT | K25: 1591 | L25: 2025 | M25: 371_293244 | N25: 46129 | O25: Артур Пак | P25: Жунусов Алихан Жасуланович | Q25: 901226350393 | T25: 10740000 | U25: 10490000 | V25: 0 | W25: 0 | X25: 250000 | Y25: 419600 | Z25: 419600 | AA25: 1s | AB25: 0.04 | AC25: =U25*AB25 -> 419600 | AD25: =AC25-V25 -> 419600 | AE25: 5 250 000.00 | AF25: 46136 | AG25: Астана | AH25: Кредит | AI25: Стандартное кредитование | AJ25: Евразийский банк | AK25: 84 месяца | AL25: 50 | AM25: 0 | AO25: 0 | AP25: 0 | AQ25: 132075977 | AS25: 11785166 | AT25: 77011057917 | AU25: САП
A26: 1 | B26: 735 Усть-Каменогорск ТОО «DCG VOSTOK» (KIA) | C26: K5 | D26: Luxe | E26: EUS42JG1J | F26: MX16A414BSK045131 | G26: AG2 Graphite Gray / Серый | H26: G155 | J26: AT | K26: 1975 | L26: 2025 | M26: 735_293887 | N26: 46139 | O26: Максим Косихин | P26: Мендыбаева Салтанат Сайлаугазовна | Q26: 780806402789 | T26: 12690000 | U26: 12690000 | V26: 0 | W26: 0 | X26: 0 | Y26: 697950 | Z26: 697950 | AA26: 1s | AB26: 0.045 | AC26: =U26*AB26 -> 571050 | AD26: =AC26-V26 -> 571050 | AE26: 12 690 000.00 | AF26: 46140 | AG26: Усть-Каменогорск | AH26: Безналичный расчет | AI26: Безналичный | AJ26: Без привлечения кредита | AM26: 0 | AN26: 381 Allur Auto Group KIA | AO26: 0 | AP26: 0 | AQ26: 132076195 | AS26: 11792267 | AT26: 77051205357 | AU26: САП
A27: 1 | B27: 331 Шымкент ТОО «DCG ONTUSTIK» (KIA) | C27: Ceed | D27: Comfort | E27: J7S6D261F | F27: MX1H1516BSK257863 | G27: HW2 Deluxe White / Белый перламутр | H27: S10W | I27: 2WD | J27: AT | K27: 1591 | L27: 2025 | M27: 331_292503 | N27: 46118 | O27: Ернар Жайдарбек | P27: Онласбеков Алмас Атирханович | Q27: 830223302676 | T27: 9690000 | U27: 9690000 | V27: 0 | W27: 0 | X27: 0 | Y27: 436050 | Z27: 436050 | AA27: 3s | AB27: 0.045 | AC27: =U27*AB27 -> 436050 | AD27: =AC27-V27 -> 436050 | AF27: 46119 | AG27: Шымкент | AH27: Безналичный расчет | AI27: Безналичный | AJ27: Без привлечения кредита | AM27: 0 | AO27: 0 | AP27: 0 | AQ27: 132074728 | AR27: 122900 | AS27: 11802657 | AT27: 77717951777 | AU27: САП
A28: 1 | B28: 735 Усть-Каменогорск ТОО «DCG VOSTOK» (KIA) | C28: Ceed SW | D28: Comfort | E28: J7W5D261F | F28: MX1H4816BSK253924 | G28: HW2 Deluxe White / Белый перламутр | H28: K0OP | I28: 2WD | J28: AT | K28: 1591 | L28: 2025 | M28: 735_293260 | N28: 46129 | O28: Азамат Тоқтарбеков | P28: Әбиев Расул Қырықбайұлы | Q28: 40216550843 | T28: 11240000 | U28: 10990000 | V28: 0 | W28: 0 | X28: 250000 | Y28: 494550 | Z28: 494550 | AA28: 1s | AB28: 0.045 | AC28: =U28*AB28 -> 494550 | AD28: =AC28-V28 -> 494550 | AE28: 1 273 135.00 | AF28: 46132 | AG28: Усть-Каменогорск | AH28: Кредит | AI28: Стандартное кредитование | AJ28: Банк ЦентрКредит | AK28: 84 месяца | AL28: 40 | AM28: 0 | AO28: 0 | AP28: 0 | AQ28: 132075524 | AR28: 127900 | AS28: 11815914 | AT28: 77476242119 | AU28: САП
